  <link
    name="BodyIndexX">
    <inertial>
      <origin
        xyz="-0.0019165 -0.020284 -1.5446E-08"
        rpy="0 0 0" />
      <mass
        value="0.2" />
      <inertia
        ixx="8.68E-05"
        ixy="-2.3313E-05"
        ixz="-3.6916E-12"
        iyy="8.6964E-05"
        iyz="2.5395E-11"
        izz="8.7186E-05" />
    </inertial>
    <visual>
      <origin
        xyz="0 0 0"
        rpy="0 0 0" />
      <geometry>
        <mesh
          filename="./meshes/BodyX.dae" />
      </geometry>
      <material
        name="">
        <color
          rgba="0.79216 0.81961 0.93333 1" />
      </material>
    </visual>
    <collision>
      <origin
        xyz="0 0 0"
        rpy="0 0 0" />
      <geometry>
        <mesh
          filename="./meshes/BodyXSimple.dae" />
      </geometry>
    </collision>
  </link>

  <link
    name="BodyIndexCenter">
    <inertial>
      <origin
        xyz="-0.0022809 -0.0021962 1.0803E-06"
        rpy="0 0 0" />
      <mass
        value="0.05" />
      <inertia
        ixx="1.0293E-05"
        ixy="8.5442E-08"
        ixz="-6.5039E-08"
        iyy="1.0301E-05"
        iyz="6.5245E-08"
        izz="9.1191E-06" />
    </inertial>
    <visual>
      <origin
        xyz="0 0 0"
        rpy="0 0 0" />
      <geometry>
        <mesh
          filename="./meshes/BodyCenter.dae" />
      </geometry>
      <material
        name="">
        <color
          rgba="0.79216 0.81961 0.93333 1" />
      </material>
    </visual>
    <collision>
      <origin
        xyz="0 0 0"
        rpy="0 0 0" />
      <geometry>
        <mesh
          filename="./meshes/BodySimpleCenter.dae" />
      </geometry>
    </collision>
  </link>

  <link
    name="BodyIndexY">
    <inertial>
      <origin
        xyz="-0.020284 -0.0019165 1.5445E-08"
        rpy="0 0 0" />
      <mass
        value="0.2" />
      <inertia
        ixx="8.6964E-05"
        ixy="-2.3313E-05"
        ixz="-2.5395E-11"
        iyy="8.68E-05"
        iyz="3.6916E-12"
        izz="8.7186E-05" />
    </inertial>
    <visual>
      <origin
        xyz="0 0 0"
        rpy="0 0 0" />
      <geometry>
        <mesh
          filename="./meshes/BodyY.dae" />
      </geometry>
      <material
        name="">
        <color
          rgba="0.79216 0.81961 0.93333 1" />
      </material>
    </visual>
    <collision>
      <origin
        xyz="0 0 0"
        rpy="0 0 0" />
      <geometry>
        <mesh
          filename="./meshes/BodyYSimple.dae" />
      </geometry>
    </collision>
  </link>

  <joint
    name="jointIndexY"
    type="revolute">
    <limit effort="1.8" lower="-1.507" upper="1.507" velocity="1.2"/>
    <origin
      xyz="0 0.0218 0"
      rpy="0 0 0" />
    <parent
      link="BodyIndexCenter" />
    <child
      link="BodyIndexY"/>
    <axis
      xyz="0 -1 0" />
  </joint>

  <joint
    name="JointIndexX"
    type="revolute">
    <limit effort="1.8" lower="-1.507" upper="1.507" velocity="1.2"/>
    <origin
      xyz="-0.0218 0 0"
      rpy="0 0 0" />
    <parent
      link="BodyIndexX" />
    <child
      link="BodyIndexCenter" />
    <axis
      xyz="1 0 0" />
  </joint>
