<?xml version="1.0" encoding="utf-8"?>
<!-- This URDF was automatically created by SolidWorks to URDF Exporter! Originally created by Stephen Brawner (brawner@gmail.com) 
     Commit Version: 1.5.1-0-g916b5db  Build Version: 1.5.7152.31018
     For more information, please see http://wiki.ros.org/sw_urdf_exporter -->
<robot
  name="all18.sldasm">
  <link
    name="base_link">
    <inertial>
      <origin
        xyz="0.0333792456099275 0.00696796132744282 -0.181820132036536"
        rpy="0 0 0" />
      <mass
        value="0.000523598775598299" />
      <inertia
        ixx="5.23598775598299E-09"
        ixy="-3.14694645605544E-41"
        ixz="-4.97841222228891E-56"
        iyy="5.23598775598299E-09"
        iyz="0"
        izz="5.23598775598299E-09" />
    </inertial>
    <visual>
      <origin
        xyz="0 0 0"
        rpy="0 0 0" />
      <geometry>
        <mesh
          filename="package://all18.sldasm/meshes/base_link.STL" />
      </geometry>
      <material
        name="">
        <color
          rgba="0.792156862745098 0.819607843137255 0.933333333333333 1" />
      </material>
    </visual>
    <collision>
      <origin
        xyz="0 0 0"
        rpy="0 0 0" />
      <geometry>
        <mesh
          filename="package://all18.sldasm/meshes/base_link.STL" />
      </geometry>
    </collision>
  </link>
  <link
    name="base">
    <inertial>
      <origin
        xyz="-0.0191214293937686 0.0210000899951462 -0.0564412527734638"
        rpy="0 0 0" />
      <mass
        value="0.497818026810933" />
      <inertia
        ixx="0.00183492237382758"
        ixy="-2.81215869790794E-09"
        ixz="-6.12233490314299E-06"
        iyy="0.000327236183202989"
        iyz="-1.52757729457466E-09"
        izz="0.00171964399163047" />
    </inertial>
    <visual>
      <origin
        xyz="0 0 0"
        rpy="0 0 0" />
      <geometry>
        <mesh
          filename="package://all18.sldasm/meshes/base.STL" />
      </geometry>
      <material
        name="">
        <color
          rgba="0.792156862745098 0.819607843137255 0.933333333333333 1" />
      </material>
    </visual>
    <collision>
      <origin
        xyz="0 0 0"
        rpy="0 0 0" />
      <geometry>
        <mesh
          filename="package://all18.sldasm/meshes/base.STL" />
      </geometry>
    </collision>
  </link>
  <joint
    name="jbase"
    type="continuous">
    <origin
      xyz="0.00400000000000071 -0.0210004689290468 -0.135354546704202"
      rpy="0 0 0" />
    <parent
      link="base_link" />
    <child
      link="base" />
    <axis
      xyz="0 1 0" />
  </joint>
  <link
    name="up">
    <inertial>
      <origin
        xyz="-0.000358969853697724 0.0210176681596711 0.143821678022038"
        rpy="0 0 0" />
      <mass
        value="0.145045484251342" />
      <inertia
        ixx="0.00183495811461002"
        ixy="1.00718350566443E-08"
        ixz="-5.28890803610092E-05"
        iyy="0.0011112557556715"
        iyz="-5.85295320638727E-08"
        izz="0.000750996955240693" />
    </inertial>
    <visual>
      <origin
        xyz="0 0 0"
        rpy="0 0 0" />
      <geometry>
        <mesh
          filename="package://all18.sldasm/meshes/up.STL" />
      </geometry>
      <material
        name="">
        <color
          rgba="0.792156862745098 0.819607843137255 0.933333333333333 1" />
      </material>
    </visual>
    <collision>
      <origin
        xyz="0 0 0"
        rpy="0 0 0" />
      <geometry>
        <mesh
          filename="package://all18.sldasm/meshes/up.STL" />
      </geometry>
    </collision>
  </link>
  <joint
    name="jup"
    type="continuous">
    <origin
      xyz="0 0 0"
      rpy="0 0 0" />
    <parent
      link="base" />
    <child
      link="up" />
    <axis
      xyz="0 1 0" />
  </joint>
  <link
    name="hl0">
    <inertial>
      <origin
        xyz="-0.012444043654672 0.0630330454718175 0.00126114384973358"
        rpy="0 0 0" />
      <mass
        value="0.0345606498251114" />
      <inertia
        ixx="4.0820399272762E-05"
        ixy="-9.51733838576895E-06"
        ixz="-3.89843594001045E-07"
        iyy="1.29632372529317E-05"
        iyz="-2.23840344717383E-06"
        izz="5.24441566488473E-05" />
    </inertial>
    <visual>
      <origin
        xyz="0 0 0"
        rpy="0 0 0" />
      <geometry>
        <mesh
          filename="package://all18.sldasm/meshes/hl0.STL" />
      </geometry>
      <material
        name="">
        <color
          rgba="0.792156862745098 0.819607843137255 0.933333333333333 1" />
      </material>
    </visual>
    <collision>
      <origin
        xyz="0 0 0"
        rpy="0 0 0" />
      <geometry>
        <mesh
          filename="package://all18.sldasm/meshes/hl0.STL" />
      </geometry>
    </collision>
  </link>
  <joint
    name="jhl0"
    type="continuous">
    <origin
      xyz="0.0119999999999987 0.126 -0.00999999999999812"
      rpy="0 0 0" />
    <parent
      link="base" />
    <child
      link="hl0" />
    <axis
      xyz="-1 0 0" />
  </joint>
  <link
    name="LGL2">
    <inertial>
      <origin
        xyz="0.0303402345828551 -0.000238949225249835 -0.0921190713255071"
        rpy="0 0 0" />
      <mass
        value="0.0480025209039811" />
      <inertia
        ixx="0.000111770026393275"
        ixy="-1.92086992344369E-09"
        ixz="0.000102318757127282"
        iyy="0.000234605578738602"
        iyz="-1.8790706655784E-08"
        izz="0.000123763363972141" />
    </inertial>
    <visual>
      <origin
        xyz="0 0 0"
        rpy="0 0 0" />
      <geometry>
        <mesh
          filename="package://all18.sldasm/meshes/LGL2.STL" />
      </geometry>
      <material
        name="">
        <color
          rgba="0.792156862745098 0.819607843137255 0.933333333333333 1" />
      </material>
    </visual>
    <collision>
      <origin
        xyz="0 0 0"
        rpy="0 0 0" />
      <geometry>
        <mesh
          filename="package://all18.sldasm/meshes/LGL2.STL" />
      </geometry>
    </collision>
  </link>
  <joint
    name="JLGL2"
    type="continuous">
    <origin
      xyz="0.0199999999999986 0.0949999999999874 0"
      rpy="0 0 0" />
    <parent
      link="hl0" />
    <child
      link="LGL2" />
    <axis
      xyz="1 0 0" />
  </joint>
  <link
    name="LGL3">
    <inertial>
      <origin
        xyz="-0.0259705484850737 -0.000999385124667941 -0.0433603663769984"
        rpy="0 0 0" />
      <mass
        value="0.0440449672148023" />
      <inertia
        ixx="7.38602754378877E-05"
        ixy="2.68585858225746E-08"
        ixz="2.22587431264711E-08"
        iyy="0.000101802073587482"
        iyz="-8.37820730757103E-06"
        izz="4.16167541378933E-05" />
    </inertial>
    <visual>
      <origin
        xyz="0 0 0"
        rpy="0 0 0" />
      <geometry>
        <mesh
          filename="package://all18.sldasm/meshes/LGL3.STL" />
      </geometry>
      <material
        name="">
        <color
          rgba="0.792156862745098 0.819607843137255 0.933333333333333 1" />
      </material>
    </visual>
    <collision>
      <origin
        xyz="0 0 0"
        rpy="0 0 0" />
      <geometry>
        <mesh
          filename="package://all18.sldasm/meshes/LGL3.STL" />
      </geometry>
    </collision>
  </link>
  <joint
    name="JLGL3"
    type="continuous">
    <origin
      xyz="0.118500000000001 0 -0.169999997278064"
      rpy="0 0 0" />
    <parent
      link="LGL2" />
    <child
      link="LGL3" />
    <axis
      xyz="-1 0 0" />
  </joint>
  <link
    name="LGL4">
    <inertial>
      <origin
        xyz="-0.0815101633243112 0.00090998729349458 0.0773021473229439"
        rpy="0 0 0" />
      <mass
        value="0.0247761471784957" />
      <inertia
        ixx="5.74694326140297E-05"
        ixy="1.68748777548126E-07"
        ixz="4.91847237830646E-05"
        iyy="0.000105893052871461"
        iyz="-8.42574317637952E-08"
        izz="4.90008441529051E-05" />
    </inertial>
    <visual>
      <origin
        xyz="0 0 0"
        rpy="0 0 0" />
      <geometry>
        <mesh
          filename="package://all18.sldasm/meshes/LGL4.STL" />
      </geometry>
      <material
        name="">
        <color
          rgba="0.792156862745098 0.819607843137255 0.933333333333333 1" />
      </material>
    </visual>
    <collision>
      <origin
        xyz="0 0 0"
        rpy="0 0 0" />
      <geometry>
        <mesh
          filename="package://all18.sldasm/meshes/LGL4.STL" />
      </geometry>
    </collision>
  </link>
  <joint
    name="JLGL4"
    type="continuous">
    <origin
      xyz="-0.0125 0.0281907786235769 0.0102606042997705"
      rpy="0 0 0" />
    <parent
      link="LGL3" />
    <child
      link="LGL4" />
    <axis
      xyz="1 0 0" />
  </joint>
  <link
    name="Q">
    <inertial>
      <origin
        xyz="0.00737924560992977 -0.221222347469288 -0.046726143074364"
        rpy="0 0 0" />
      <mass
        value="0.000523598775598299" />
      <inertia
        ixx="5.23598775598299E-09"
        ixy="-3.14694645605544E-41"
        ixz="-4.97841222228891E-56"
        iyy="5.23598775598299E-09"
        iyz="0"
        izz="5.23598775598299E-09" />
    </inertial>
    <visual>
      <origin
        xyz="0 0 0"
        rpy="0 0 0" />
      <geometry>
        <mesh
          filename="package://all18.sldasm/meshes/Q.STL" />
      </geometry>
      <material
        name="">
        <color
          rgba="0.792156862745098 0.819607843137255 0.933333333333333 1" />
      </material>
    </visual>
    <collision>
      <origin
        xyz="0 0 0"
        rpy="0 0 0" />
      <geometry>
        <mesh
          filename="package://all18.sldasm/meshes/Q.STL" />
      </geometry>
    </collision>
  </link>
  <joint
    name="JQ"
    type="continuous">
    <origin
      xyz="-0.116000000000001 0 0.169999999744713"
      rpy="0 0 0" />
    <parent
      link="LGL4" />
    <child
      link="Q" />
    <axis
      xyz="1 0 0" />
  </joint>
  <link
    name="hl1">
    <inertial>
      <origin
        xyz="0.0133498937147595 -0.0238046214490557 -0.172664834958128"
        rpy="0 0 0" />
      <mass
        value="1.01104308189925" />
      <inertia
        ixx="0.00145265002912084"
        ixy="8.0433424924099E-05"
        ixz="-0.000112470355803545"
        iyy="0.00176407136725321"
        iyz="-1.28353527421716E-05"
        izz="0.000926948423015179" />
    </inertial>
    <visual>
      <origin
        xyz="0 0 0"
        rpy="0 0 0" />
      <geometry>
        <mesh
          filename="package://all18.sldasm/meshes/hl1.STL" />
      </geometry>
      <material
        name="">
        <color
          rgba="0.792156862745098 0.819607843137255 0.933333333333333 1" />
      </material>
    </visual>
    <collision>
      <origin
        xyz="0 0 0"
        rpy="0 0 0" />
      <geometry>
        <mesh
          filename="package://all18.sldasm/meshes/hl1.STL" />
      </geometry>
    </collision>
  </link>
  <joint
    name="jhl1"
    type="continuous">
    <origin
      xyz="-0.0260000021964453 0.00514093216985746 -0.06179130036624"
      rpy="0 0 0" />
    <parent
      link="LGL3" />
    <child
      link="hl1" />
    <axis
      xyz="0 1 0" />
  </joint>
  <link
    name="kl">
    <inertial>
      <origin
        xyz="0.0333224268442176 -0.0406715046714338 -0.0929075490419892"
        rpy="0 0 0" />
      <mass
        value="0.0788046240275913" />
      <inertia
        ixx="0.000272384188746931"
        ixy="1.63113405200858E-05"
        ixz="2.0707066924017E-05"
        iyy="0.000195539432878404"
        iyz="-7.85136563050533E-05"
        izz="0.000101363064081106" />
    </inertial>
    <visual>
      <origin
        xyz="0 0 0"
        rpy="0 0 0" />
      <geometry>
        <mesh
          filename="package://all18.sldasm/meshes/kl.STL" />
      </geometry>
      <material
        name="">
        <color
          rgba="0.792156862745098 0.819607843137255 0.933333333333333 1" />
      </material>
    </visual>
    <collision>
      <origin
        xyz="0 0 0"
        rpy="0 0 0" />
      <geometry>
        <mesh
          filename="package://all18.sldasm/meshes/kl.STL" />
      </geometry>
    </collision>
  </link>
  <joint
    name="jkl"
    type="continuous">
    <origin
      xyz="-0.00552885197136085 -0.0155925666722328 -0.466487667780456"
      rpy="0 0 0" />
    <parent
      link="hl1" />
    <child
      link="kl" />
    <axis
      xyz="0 1 0" />
  </joint>
  <link
    name="laz">
    <inertial>
      <origin
        xyz="0.00323260978148331 -3.41763886635427E-09 -0.0781723384397688"
        rpy="0 0 0" />
      <mass
        value="0.017465708692541" />
      <inertia
        ixx="1.07154278113196E-05"
        ixy="2.15904603301283E-11"
        ixz="-3.72523751477519E-07"
        iyy="1.14184647460219E-05"
        iyz="1.41917143060981E-11"
        izz="1.01857895731504E-06" />
    </inertial>
    <visual>
      <origin
        xyz="0 0 0"
        rpy="0 0 0" />
      <geometry>
        <mesh
          filename="package://all18.sldasm/meshes/laz.STL" />
      </geometry>
      <material
        name="">
        <color
          rgba="0.792156862745098 0.819607843137255 0.933333333333333 1" />
      </material>
    </visual>
    <collision>
      <origin
        xyz="0 0 0"
        rpy="0 0 0" />
      <geometry>
        <mesh
          filename="package://all18.sldasm/meshes/laz.STL" />
      </geometry>
    </collision>
  </link>
  <joint
    name="jlaz"
    type="continuous">
    <origin
      xyz="0.0627688477282864 -0.0624533739550739 -0.14875730407774"
      rpy="0 0 0" />
    <parent
      link="kl" />
    <child
      link="laz" />
    <axis
      xyz="-0.0180338394426846 0 -0.999837377094373" />
  </joint>
  <link
    name="LGL5">
    <inertial>
      <origin
        xyz="-0.0295043372043891 -0.0463054507876196 5.2106408894359E-05"
        rpy="0 0 0" />
      <mass
        value="0.0149926496755023" />
      <inertia
        ixx="1.23694306884942E-05"
        ixy="-3.04663709334515E-06"
        ixz="1.00130982367423E-10"
        iyy="1.39553354047269E-06"
        iyz="-6.49001565136249E-10"
        izz="1.34138114240442E-05" />
    </inertial>
    <visual>
      <origin
        xyz="0 0 0"
        rpy="0 0 0" />
      <geometry>
        <mesh
          filename="package://all18.sldasm/meshes/LGL5.STL" />
      </geometry>
      <material
        name="">
        <color
          rgba="0.752941176470588 0.752941176470588 0.752941176470588 1" />
      </material>
    </visual>
    <collision>
      <origin
        xyz="0 0 0"
        rpy="0 0 0" />
      <geometry>
        <mesh
          filename="package://all18.sldasm/meshes/LGL5.STL" />
      </geometry>
    </collision>
  </link>
  <joint
    name="JLGL5"
    type="continuous">
    <origin
      xyz="-0.00749999999999955 0 -0.04999999763965"
      rpy="0 0 0" />
    <parent
      link="LGL2" />
    <child
      link="LGL5" />
    <axis
      xyz="1 0 0" />
  </joint>
  <link
    name="W">
    <inertial>
      <origin
        xyz="0.0258792456099279 -0.0980315697435112 0.0135344146676633"
        rpy="0 0 0" />
      <mass
        value="0.000523598775598299" />
      <inertia
        ixx="5.23598775598299E-09"
        ixy="-3.14694645605544E-41"
        ixz="-4.97841222228891E-56"
        iyy="5.23598775598299E-09"
        iyz="0"
        izz="5.23598775598299E-09" />
    </inertial>
    <visual>
      <origin
        xyz="0 0 0"
        rpy="0 0 0" />
      <geometry>
        <mesh
          filename="package://all18.sldasm/meshes/W.STL" />
      </geometry>
      <material
        name="">
        <color
          rgba="0.792156862745098 0.819607843137255 0.933333333333333 1" />
      </material>
    </visual>
    <collision>
      <origin
        xyz="0 0 0"
        rpy="0 0 0" />
      <geometry>
        <mesh
          filename="package://all18.sldasm/meshes/W.STL" />
      </geometry>
    </collision>
  </link>
  <joint
    name="JW"
    type="continuous">
    <origin
      xyz="-0.0209999999999989 -0.0949999999999889 0"
      rpy="0 0 0" />
    <parent
      link="LGL5" />
    <child
      link="W" />
    <axis
      xyz="1 0 0" />
  </joint>
  <link
    name="hr0">
    <inertial>
      <origin
        xyz="-0.0124440425839899 -0.0630330438495321 0.00126112872924455"
        rpy="0 0 0" />
      <mass
        value="0.0345606512450045" />
      <inertia
        ixx="4.08203810730217E-05"
        ixy="9.51733756197713E-06"
        ixz="-3.89838276140267E-07"
        iyy="1.29632324198126E-05"
        iyz="2.23837388192549E-06"
        izz="5.24441456477098E-05" />
    </inertial>
    <visual>
      <origin
        xyz="0 0 0"
        rpy="0 0 0" />
      <geometry>
        <mesh
          filename="package://all18.sldasm/meshes/hr0.STL" />
      </geometry>
      <material
        name="">
        <color
          rgba="0.792156862745098 0.819607843137255 0.933333333333333 1" />
      </material>
    </visual>
    <collision>
      <origin
        xyz="0 0 0"
        rpy="0 0 0" />
      <geometry>
        <mesh
          filename="package://all18.sldasm/meshes/hr0.STL" />
      </geometry>
    </collision>
  </link>
  <joint
    name="jhr0"
    type="continuous">
    <origin
      xyz="0.0120000000000003 -0.0840000000000005 -0.010000000000002"
      rpy="0 0 0" />
    <parent
      link="base" />
    <child
      link="hr0" />
    <axis
      xyz="-1 0 0" />
  </joint>
  <link
    name="LGR2">
    <inertial>
      <origin
        xyz="0.0303402875277209 0.000238954351489296 -0.0921190918466555"
        rpy="0 0 0" />
      <mass
        value="0.0480025630196165" />
      <inertia
        ixx="0.000111770056835883"
        ixy="1.90833891765353E-09"
        ixz="0.00010231881547354"
        iyy="0.000234605746064627"
        iyz="1.87952281801939E-08"
        izz="0.00012376350264109" />
    </inertial>
    <visual>
      <origin
        xyz="0 0 0"
        rpy="0 0 0" />
      <geometry>
        <mesh
          filename="package://all18.sldasm/meshes/LGR2.STL" />
      </geometry>
      <material
        name="">
        <color
          rgba="0.792156862745098 0.819607843137255 0.933333333333333 1" />
      </material>
    </visual>
    <collision>
      <origin
        xyz="0 0 0"
        rpy="0 0 0" />
      <geometry>
        <mesh
          filename="package://all18.sldasm/meshes/LGR2.STL" />
      </geometry>
    </collision>
  </link>
  <joint
    name="JLGR2"
    type="continuous">
    <origin
      xyz="0.020000000000001 -0.0949999999999869 0"
      rpy="0 0 0" />
    <parent
      link="hr0" />
    <child
      link="LGR2" />
    <axis
      xyz="1 0 0" />
  </joint>
  <link
    name="LGR3">
    <inertial>
      <origin
        xyz="-0.026029451797925 0.000999385107291528 -0.0433603662950159"
        rpy="0 0 0" />
      <mass
        value="0.0440449673833386" />
      <inertia
        ixx="7.38602755028676E-05"
        ixy="2.68584144567964E-08"
        ixz="-2.225841178535E-08"
        iyy="0.000101802073674459"
        iyz="8.37820731923215E-06"
        izz="4.16167541380746E-05" />
    </inertial>
    <visual>
      <origin
        xyz="0 0 0"
        rpy="0 0 0" />
      <geometry>
        <mesh
          filename="package://all18.sldasm/meshes/LGR3.STL" />
      </geometry>
      <material
        name="">
        <color
          rgba="0.792156862745098 0.819607843137255 0.933333333333333 1" />
      </material>
    </visual>
    <collision>
      <origin
        xyz="0 0 0"
        rpy="0 0 0" />
      <geometry>
        <mesh
          filename="package://all18.sldasm/meshes/LGR3.STL" />
      </geometry>
    </collision>
  </link>
  <joint
    name="JLGR3"
    type="continuous">
    <origin
      xyz="0.118500000000001 0 -0.169999997278063"
      rpy="0 0 0" />
    <parent
      link="LGR2" />
    <child
      link="LGR3" />
    <axis
      xyz="-1 0 0" />
  </joint>
  <link
    name="LGR4">
    <inertial>
      <origin
        xyz="-0.0815099189923016 -0.000909987478768359 0.0773019618123106"
        rpy="0 0 0" />
      <mass
        value="0.024775859664522" />
      <inertia
        ixx="5.74693498807819E-05"
        ixy="-1.68752282875726E-07"
        ixz="4.91845861894577E-05"
        iyy="0.000105892734837817"
        iyz="8.42598805758962E-08"
        izz="4.90006086288347E-05" />
    </inertial>
    <visual>
      <origin
        xyz="0 0 0"
        rpy="0 0 0" />
      <geometry>
        <mesh
          filename="package://all18.sldasm/meshes/LGR4.STL" />
      </geometry>
      <material
        name="">
        <color
          rgba="0.792156862745098 0.819607843137255 0.933333333333333 1" />
      </material>
    </visual>
    <collision>
      <origin
        xyz="0 0 0"
        rpy="0 0 0" />
      <geometry>
        <mesh
          filename="package://all18.sldasm/meshes/LGR4.STL" />
      </geometry>
    </collision>
  </link>
  <joint
    name="JLGR4"
    type="continuous">
    <origin
      xyz="-0.0124999999999998 -0.0281907786235776 0.0102606042997697"
      rpy="0 0 0" />
    <parent
      link="LGR3" />
    <child
      link="LGR4" />
    <axis
      xyz="1 0 0" />
  </joint>
  <link
    name="QQ">
    <inertial>
      <origin
        xyz="0.0258792456099257 0.111968430256489 0.0135344146676662"
        rpy="0 0 0" />
      <mass
        value="0.000523598775598299" />
      <inertia
        ixx="5.23598775598299E-09"
        ixy="-3.14694645605544E-41"
        ixz="-4.97841222228891E-56"
        iyy="5.23598775598299E-09"
        iyz="0"
        izz="5.23598775598299E-09" />
    </inertial>
    <visual>
      <origin
        xyz="0 0 0"
        rpy="0 0 0" />
      <geometry>
        <mesh
          filename="package://all18.sldasm/meshes/QQ.STL" />
      </geometry>
      <material
        name="">
        <color
          rgba="0.792156862745098 0.819607843137255 0.933333333333333 1" />
      </material>
    </visual>
    <collision>
      <origin
        xyz="0 0 0"
        rpy="0 0 0" />
      <geometry>
        <mesh
          filename="package://all18.sldasm/meshes/QQ.STL" />
      </geometry>
    </collision>
  </link>
  <joint
    name="JQQ"
    type="continuous">
    <origin
      xyz="-0.134500000000002 0.123200094236836 0.109739442002689"
      rpy="0 0 0" />
    <parent
      link="LGR4" />
    <child
      link="QQ" />
    <axis
      xyz="1 0 0" />
  </joint>
  <link
    name="hr1">
    <inertial>
      <origin
        xyz="0.0130834240735185 0.0237236363780169 -0.172316052457163"
        rpy="0 0 0" />
      <mass
        value="1.00830188359462" />
      <inertia
        ixx="0.00145122644714664"
        ixy="-7.95874934733648E-05"
        ixz="-0.000118810763484627"
        iyy="0.00176339063031824"
        iyz="1.43734483789115E-05"
        izz="0.000927671733876011" />
    </inertial>
    <visual>
      <origin
        xyz="0 0 0"
        rpy="0 0 0" />
      <geometry>
        <mesh
          filename="package://all18.sldasm/meshes/hr1.STL" />
      </geometry>
      <material
        name="">
        <color
          rgba="0.792156862745098 0.819607843137255 0.933333333333333 1" />
      </material>
    </visual>
    <collision>
      <origin
        xyz="0 0 0"
        rpy="0 0 0" />
      <geometry>
        <mesh
          filename="package://all18.sldasm/meshes/hr1.STL" />
      </geometry>
    </collision>
  </link>
  <joint
    name="jhr1"
    type="continuous">
    <origin
      xyz="-0.0259999978035542 -0.00514093216985634 -0.0617913003662402"
      rpy="0 0 0" />
    <parent
      link="LGR3" />
    <child
      link="hr1" />
    <axis
      xyz="0 -1 0" />
  </joint>
  <link
    name="kr">
    <inertial>
      <origin
        xyz="0.0372507288202393 0.0459505488503911 -0.107920415168121"
        rpy="0 0 0" />
      <mass
        value="0.0678333218810008" />
      <inertia
        ixx="0.000268701652086822"
        ixy="-1.63973572747645E-05"
        ixz="1.97678140358497E-05"
        iyy="0.000190432746251649"
        iyz="7.84641148535466E-05"
        izz="9.97855116434662E-05" />
    </inertial>
    <visual>
      <origin
        xyz="0 0 0"
        rpy="0 0 0" />
      <geometry>
        <mesh
          filename="package://all18.sldasm/meshes/kr.STL" />
      </geometry>
      <material
        name="">
        <color
          rgba="0.792156862745098 0.819607843137255 0.933333333333333 1" />
      </material>
    </visual>
    <collision>
      <origin
        xyz="0 0 0"
        rpy="0 0 0" />
      <geometry>
        <mesh
          filename="package://all18.sldasm/meshes/kr.STL" />
      </geometry>
    </collision>
  </link>
  <joint
    name="jkr"
    type="continuous">
    <origin
      xyz="-0.00948768787127001 0.0160925667691815 -0.466663550621361"
      rpy="0 0 0" />
    <parent
      link="hr1" />
    <child
      link="kr" />
    <axis
      xyz="0 -1 0" />
  </joint>
  <link
    name="LGR5">
    <inertial>
      <origin
        xyz="-0.0295043372043607 0.0463054508388104 -5.20609183857212E-05"
        rpy="0 0 0" />
      <mass
        value="0.0149926496755723" />
      <inertia
        ixx="1.23694306885358E-05"
        ixy="3.04663709344402E-06"
        ixz="-9.71379620432482E-11"
        iyy="1.39553354176249E-06"
        iyz="-6.60808333419368E-10"
        izz="1.34138114228007E-05" />
    </inertial>
    <visual>
      <origin
        xyz="0 0 0"
        rpy="0 0 0" />
      <geometry>
        <mesh
          filename="package://all18.sldasm/meshes/LGR5.STL" />
      </geometry>
      <material
        name="">
        <color
          rgba="0.752941176470588 0.752941176470588 0.752941176470588 1" />
      </material>
    </visual>
    <collision>
      <origin
        xyz="0 0 0"
        rpy="0 0 0" />
      <geometry>
        <mesh
          filename="package://all18.sldasm/meshes/LGR5.STL" />
      </geometry>
    </collision>
  </link>
  <joint
    name="JLGR5"
    type="continuous">
    <origin
      xyz="-0.00749999999999906 0 -0.0499999976396491"
      rpy="0 0 0" />
    <parent
      link="LGR2" />
    <child
      link="LGR5" />
    <axis
      xyz="1 0 0" />
  </joint>
  <link
    name="WW">
    <inertial>
      <origin
        xyz="0.0783125137450799 0.228931139718852 -0.341303438274219"
        rpy="0 0 0" />
      <mass
        value="3.24600512308579" />
      <inertia
        ixx="0.334434496720483"
        ixy="-0.00015351158430259"
        ixz="0.0460392899400449"
        iyy="0.260169463432138"
        iyz="0.00080043000726521"
        izz="0.107481102111202" />
    </inertial>
    <visual>
      <origin
        xyz="0 0 0"
        rpy="0 0 0" />
      <geometry>
        <mesh
          filename="package://all18.sldasm/meshes/WW.STL" />
      </geometry>
      <material
        name="">
        <color
          rgba="1 1 1 1" />
      </material>
    </visual>
    <collision>
      <origin
        xyz="0 0 0"
        rpy="0 0 0" />
      <geometry>
        <mesh
          filename="package://all18.sldasm/meshes/WW.STL" />
      </geometry>
    </collision>
  </link>
  <joint
    name="JWW"
    type="continuous">
    <origin
      xyz="-0.00250000000000023 -0.0281907777257897 0.0602606044060692"
      rpy="0 0 0" />
    <parent
      link="LGR5" />
    <child
      link="WW" />
    <axis
      xyz="1 0 0" />
  </joint>
</robot>